ch_request
    result = await self.handle_user_exception(error)
             ^^^^^^^^^^^^^^^^^^^^^^^^^^^^^^^^^^^^^^^
  File "/home/runner/TelegramLoginWidget/.pythonlibs/lib/python3.11/site-packages/quart/app.py", line 1029, in handle_user_exception
    raise error
  File "/home/runner/TelegramLoginWidget/.pythonlibs/lib/python3.11/site-packages/quart/app.py", line 1439, in full_dispatch_request
    result = await self.dispatch_request(request_context)
             ^^^^^^^^^^^^^^^^^^^^^^^^^^^^^^^^^^^^^^^^^^^^
  File "/home/runner/TelegramLoginWidget/.pythonlibs/lib/python3.11/site-packages/quart/app.py", line 1535, in dispatch_request
    return await self.ensure_async(handler)(**request_.view_args)  # type: ignore
           ^^^^^^^^^^^^^^^^^^^^^^^^^^^^^^^^^^^^^^^^^^^^^^^^^^^^^^
  File "/home/runner/TelegramLoginWidget/app.py", line 33, in index
    return await render_template('index.html')
           ^^^^^^^^^^^^^^^^^^^^^^^^^^^^^^^^^^^
  File "/home/runner/TelegramLoginWidget/.pythonlibs/lib/python3.11/site-packages/quart/templating.py", line 47, in render_template
    return await _render(template, context, current_app._get_current_object())  # type: ignore
           ^^^^^^^^^^^^^^^^^^^^^^^^^^^^^^^^^^^^^^^^^^^^^^^^^^^^^^^^^^^^^^^^^^^
  File "/home/runner/TelegramLoginWidget/.pythonlibs/lib/python3.11/site-packages/quart/templating.py", line 66, in _render
    rendered_template = await template.render_async(context)
                        ^^^^^^^^^^^^^^^^^^^^^^^^^^^^^^^^^^^^
  File "/home/runner/TelegramLoginWidget/.pythonlibs/lib/python3.11/site-packages/jinja2/environment.py", line 1327, in render_async
    return self.environment.handle_exception()
           ^^^^^^^^^^^^^^^^^^^^^^^^^^^^^^^^^^^
  File "/home/runner/TelegramLoginWidget/.pythonlibs/lib/python3.11/site-packages/jinja2/environment.py", line 939, in handle_exception
    raise rewrite_traceback_stack(source=source)
  File "/home/runner/TelegramLoginWidget/.pythonlibs/lib/python3.11/site-packages/jinja2/environment.py", line 1324, in <listcomp>
    [n async for n in self.root_render_func(ctx)]  # type: ignore
    ^^^^^^^^^^^^^^^^^^^^^^^^^^^^^^^^^^^^^^^^^^^^^
  File "/home/runner/TelegramLoginWidget/templates/index.html", line 1, in top-level template code
    {% extends "base.html" %}
  File "/home/runner/TelegramLoginWidget/templates/base.html", line 15, in top-level template code
    <li><a href="{{ url_for('profile') }}">Profile</a></li>
    ^^^^^^^^^^^^^^^^^^^^^^^^^
  File "/home/runner/TelegramLoginWidget/.pythonlibs/lib/python3.11/site-packages/quart/app.py", line 734, in url_for
    return self.handle_url_build_error(error, endpoint, values)
           ^^^^^^^^^^^^^^^^^^^^^^^^^^^^^^^^^^^^^^^^^^^^^^^^^^^^
  File "/home/runner/TelegramLoginWidget/.pythonlibs/lib/python3.11/site-packages/quart/app.py", line 732, in url_for
    url = url_adapter.build(endpoint, values, method=_method, force_external=_external)
          ^^^^^^^^^^^^^^^^^^^^^^^^^^^^^^^^^^^^^^^^^^^^^^^^^^^^^^^^^^^^^^^^^^^^^^^^^^^^^
  File "/home/runner/TelegramLoginWidget/.pythonlibs/lib/python3.11/site-packages/werkzeug/routing/map.py", line 924, in build
    raise BuildError(endpoint, values, method, self)
werkzeug.routing.exceptions.BuildError: Could not build url for endpoint 'profile'. Did you mean 'index' instead?
[2024-09-24 20:18:30 +0000] [4064] [ERROR] Error in ASGI Framework
Traceback (most recent call last):
  File "/home/runner/TelegramLoginWidget/.pythonlibs/lib/python3.11/site-packages/quart/app.py", line 1403, in handle_request
    return await self.full_dispatch_request(request_context)
           ^^^^^^^^^^^^^^^^^^^^^^^^^^^^^^^^^^^^^^^^^^^^^^^^^
  File "/home/runner/TelegramLoginWidget/.pythonlibs/lib/python3.11/site-packages/quart/app.py", line 1441, in full_dispatch_request
    result = await self.handle_user_exception(error)
             ^^^^^^^^^^^^^^^^^^^^^^^^^^^^^^^^^^^^^^^
  File "/home/runner/TelegramLoginWidget/.pythonlibs/lib/python3.11/site-packages/quart/app.py", line 1029, in handle_user_exception
    raise error
  File "/home/runner/TelegramLoginWidget/.pythonlibs/lib/python3.11/site-packages/quart/app.py", line 1439, in full_dispatch_request
    result = await self.dispatch_request(request_context)
             ^^^^^^^^^^^^^^^^^^^^^^^^^^^^^^^^^^^^^^^^^^^^
  File "/home/runner/TelegramLoginWidget/.pythonlibs/lib/python3.11/site-packages/quart/app.py", line 1535, in dispatch_request
    return await self.ensure_async(handler)(**request_.view_args)  # type: ignore
           ^^^^^^^^^^^^^^^^^^^^^^^^^^^^^^^^^^^^^^^^^^^^^^^^^^^^^^
  File "/home/runner/TelegramLoginWidget/app.py", line 33, in index
    return await render_template('index.html')
           ^^^^^^^^^^^^^^^^^^^^^^^^^^^^^^^^^^^
  File "/home/runner/TelegramLoginWidget/.pythonlibs/lib/python3.11/site-packages/quart/templating.py", line 47, in render_template
    return await _render(template, context, current_app._get_current_object())  # type: ignore
           ^^^^^^^^^^^^^^^^^^^^^^^^^^^^^^^^^^^^^^^^^^^^^^^^^^^^^^^^^^^^^^^^^^^
  File "/home/runner/TelegramLoginWidget/.pythonlibs/lib/python3.11/site-packages/quart/templating.py", line 66, in _render
    rendered_template = await template.render_async(context)
                        ^^^^^^^^^^^^^^^^^^^^^^^^^^^^^^^^^^^^
  File "/home/runner/TelegramLoginWidget/.pythonlibs/lib/python3.11/site-packages/jinja2/environment.py", line 1327, in render_async
    return self.environment.handle_exception()
           ^^^^^^^^^^^^^^^^^^^^^^^^^^^^^^^^^^^
  File "/home/runner/TelegramLoginWidget/.pythonlibs/lib/python3.11/site-packages/jinja2/environment.py", line 939, in handle_exception
    raise rewrite_traceback_stack(source=source)
  File "/home/runner/TelegramLoginWidget/.pythonlibs/lib/python3.11/site-packages/jinja2/environment.py", line 1324, in <listcomp>
    [n async for n in self.root_render_func(ctx)]  # type: ignore
    ^^^^^^^^^^^^^^^^^^^^^^^^^^^^^^^^^^^^^^^^^^^^^
  File "/home/runner/TelegramLoginWidget/templates/index.html", line 1, in top-level template code
    {% extends "base.html" %}
  File "/home/runner/TelegramLoginWidget/templates/base.html", line 15, in top-level template code
    <li><a href="{{ url_for('profile') }}">Profile</a></li>
    ^^^^^^^^^^^^^^^^^^^^^^^^^
  File "/home/runner/TelegramLoginWidget/.pythonlibs/lib/python3.11/site-packages/quart/app.py", line 734, in url_for
    return self.handle_url_build_error(error, endpoint, values)
           ^^^^^^^^^^^^^^^^^^^^^^^^^^^^^^^^^^^^^^^^^^^^^^^^^^^^
  File "/home/runner/TelegramLoginWidget/.pythonlibs/lib/python3.11/site-packages/quart/app.py", line 732, in url_for
    url = url_adapter.build(endpoint, values, method=_method, force_external=_external)
          ^^^^^^^^^^^^^^^^^^^^^^^^^^^^^^^^^^^^^^^^^^^^^^^^^^^^^^^^^^^^^^^^^^^^^^^^^^^^^
  File "/home/runner/TelegramLoginWidget/.pythonlibs/lib/python3.11/site-packages/werkzeug/routing/map.py", line 924, in build
    raise BuildError(endpoint, values, method, self)
werkzeug.routing.exceptions.BuildError: Could not build url for endpoint 'profile'. Did you mean 'index' instead?

During handling of the above exception, another exception occurred:

Traceback (most recent call last):
  File "/home/runner/TelegramLoginWidget/.pythonlibs/lib/python3.11/site-packages/hypercorn/asyncio/task_group.py", line 27, in _handle
    await app(scope, receive, send, sync_spawn, call_soon)
  File "/home/runner/TelegramLoginWidget/.pythonlibs/lib/python3.11/site-packages/hypercorn/app_wrappers.py", line 34, in __call__
    await self.app(scope, receive, send)
  File "/home/runner/TelegramLoginWidget/.pythonlibs/lib/python3.11/site-packages/quart/app.py", line 1667, in __call__
    await self.asgi_app(scope, receive, send)
  File "/home/runner/TelegramLoginWidget/.pythonlibs/lib/python3.11/site-packages/quart/app.py", line 1693, in asgi_app
    await asgi_handler(receive, send)
  File "/home/runner/TelegramLoginWidget/.pythonlibs/lib/python3.11/site-packages/quart/asgi.py", line 52, in __call__
    raise_task_exceptions(done)
  File "/home/runner/TelegramLoginWidget/.pythonlibs/lib/python3.11/site-packages/quart/utils.py", line 180, in raise_task_exceptions
    raise task.exception()
  File "/home/runner/TelegramLoginWidget/.pythonlibs/lib/python3.11/site-packages/quart/asgi.py", line 100, in handle_request
    response = await _handle_exception(self.app, error)
               ^^^^^^^^^^^^^^^^^^^^^^^^^^^^^^^^^^^^^^^^
  File "/home/runner/TelegramLoginWidget/.pythonlibs/lib/python3.11/site-packages/quart/asgi.py", line 357, in _handle_exception
    raise error
  File "/home/runner/TelegramLoginWidget/.pythonlibs/lib/python3.11/site-packages/quart/asgi.py", line 98, in handle_request
    response = await self.app.handle_request(request)
               ^^^^^^^^^^^^^^^^^^^^^^^^^^^^^^^^^^^^^^
  File "/home/runner/TelegramLoginWidget/.pythonlibs/lib/python3.11/site-packages/quart/app.py", line 1407, in handle_request
    return await self.handle_exception(error)
           ^^^^^^^^^^^^^^^^^^^^^^^^^^^^^^^^^^
  File "/home/runner/TelegramLoginWidget/.pythonlibs/lib/python3.11/site-packages/quart/app.py", line 1061, in handle_exception
    server_error = await self.ensure_async(handler)(server_error)  # type: ignore
                   ^^^^^^^^^^^^^^^^^^^^^^^^^^^^^^^^^^^^^^^^^^^^^^
  File "/home/runner/TelegramLoginWidget/app.py", line 94, in internal_error
    return await render_template('errors/500.html'), 500
           ^^^^^^^^^^^^^^^^^^^^^^^^^^^^^^^^^^^^^^^^
  File "/home/runner/TelegramLoginWidget/.pythonlibs/lib/python3.11/site-packages/quart/templating.py", line 47, in render_template
    return await _render(template, context, current_app._get_current_object())  # type: ignore
           ^^^^^^^^^^^^^^^^^^^^^^^^^^^^^^^^^^^^^^^^^^^^^^^^^^^^^^^^^^^^^^^^^^^
  File "/home/runner/TelegramLoginWidget/.pythonlibs/lib/python3.11/site-packages/quart/templating.py", line 66, in _render
    rendered_template = await template.render_async(context)
                        ^^^^^^^^^^^^^^^^^^^^^^^^^^^^^^^^^^^^
  File "/home/runner/TelegramLoginWidget/.pythonlibs/lib/python3.11/site-packages/jinja2/environment.py", line 1327, in render_async
    return self.environment.handle_exception()
           ^^^^^^^^^^^^^^^^^^^^^^^^^^^^^^^^^^^
  File "/home/runner/TelegramLoginWidget/.pythonlibs/lib/python3.11/site-packages/jinja2/environment.py", line 939, in handle_exception
    raise rewrite_traceback_stack(source=source)
  File "/home/runner/TelegramLoginWidget/.pythonlibs/lib/python3.11/site-packages/jinja2/environment.py", line 1324, in <listcomp>
    [n async for n in self.root_render_func(ctx)]  # type: ignore
    ^^^^^^^^^^^^^^^^^^^^^^^^^^^^^^^^^^^^^^^^^^^^^
  File "/home/runner/TelegramLoginWidget/templates/errors/500.html", line 1, in top-level template code
    {% extends 'base.html' %}
  File "/home/runner/TelegramLoginWidget/templates/base.html", line 15, in top-level template code
    <li><a href="{{ url_for('profile') }}">Profile</a></li>
    ^^^^^^^^^^^^^^^^^^^^^^^^^
  File "/home/runner/TelegramLoginWidget/.pythonlibs/lib/python3.11/site-packages/quart/app.py", line 734, in url_for
    return self.handle_url_build_error(error, endpoint, values)
           ^^^^^^^^^^^^^^^^^^^^^^^^^^^^^^^^^^^^^^^^^^^^^^^^^^^^
  File "/home/runner/TelegramLoginWidget/.pythonlibs/lib/python3.11/site-packages/quart/app.py", line 732, in url_for
    url = url_adapter.build(endpoint, values, method=_method, force_external=_external)
          ^^^^^^^^^^^^^^^^^^^^^^^^^^^^^^^^^^^^^^^^^^^^^^^^^^^^^^^^^^^^^^^^^^^^^^^^^^^^^
  File "/home/runner/TelegramLoginWidget/.pythonlibs/lib/python3.11/site-packages/werkzeug/routing/map.py", line 924, in build
    raise BuildError(endpoint, values, method, self)
werkzeug.routing.exceptions.BuildError: Could not build url for endpoint 'profile'. Did you mean 'index' instead?
2024-09-24 20:18:30,712 - hypercorn.error - ERROR - Error in ASGI Framework
Traceback (most recent call last):
  File "/home/runner/TelegramLoginWidget/.pythonlibs/lib/python3.11/site-packages/quart/app.py", line 1403, in handle_request
    return await self.full_dispatch_request(request_context)
           ^^^^^^^^^^^^^^^^^^^^^^^^^^^^^^^^^^^^^^^^^^^^^^^^^
  File "/home/runner/TelegramLoginWidget/.pythonlibs/lib/python3.11/site-packages/quart/app.py", line 1441, in full_dispatch_request
    result = await self.handle_user_exception(error)
             ^^^^^^^^^^^^^^^^^^^^^^^^^^^^^^^^^^^^^^^
  File "/home/runner/TelegramLoginWidget/.pythonlibs/lib/python3.11/site-packages/quart/app.py", line 1029, in handle_user_exception
    raise error
  File "/home/runner/TelegramLoginWidget/.pythonlibs/lib/python3.11/site-packages/quart/app.py", line 1439, in full_dispatch_request
    result = await self.dispatch_request(request_context)
             ^^^^^^^^^^^^^^^^^^^^^^^^^^^^^^^^^^^^^^^^^^^^
  File "/home/runner/TelegramLoginWidget/.pythonlibs/lib/python3.11/site-packages/quart/app.py", line 1535, in dispatch_request
    return await self.ensure_async(handler)(**request_.view_args)  # type: ignore
           ^^^^^^^^^^^^^^^^^^^^^^^^^^^^^^^^^^^^^^^^^^^^^^^^^^^^^^
  File "/home/runner/TelegramLoginWidget/app.py", line 33, in index
    return await render_template('index.html')
           ^^^^^^^^^^^^^^^^^^^^^^^^^^^^^^^^^^^
  File "/home/runner/TelegramLoginWidget/.pythonlibs/lib/python3.11/site-packages/quart/templating.py", line 47, in render_template
    return await _render(template, context, current_app._get_current_object())  # type: ignore
           ^^^^^^^^^^^^^^^^^^^^^^^^^^^^^^^^^^^^^^^^^^^^^^^^^^^^^^^^^^^^^^^^^^^
  File "/home/runner/TelegramLoginWidget/.pythonlibs/lib/python3.11/site-packages/quart/templating.py", line 66, in _render
    rendered_template = await template.render_async(context)
                        ^^^^^^^^^^^^^^^^^^^^^^^^^^^^^^^^^^^^
  File "/home/runner/TelegramLoginWidget/.pythonlibs/lib/python3.11/site-packages/jinja2/environment.py", line 1327, in render_async
    return self.environment.handle_exception()
           ^^^^^^^^^^^^^^^^^^^^^^^^^^^^^^^^^^^
  File "/home/runner/TelegramLoginWidget/.pythonlibs/lib/python3.11/site-packages/jinja2/environment.py", line 939, in handle_exception
    raise rewrite_traceback_stack(source=source)
  File "/home/runner/TelegramLoginWidget/.pythonlibs/lib/python3.11/site-packages/jinja2/environment.py", line 1324, in <listcomp>
    [n async for n in self.root_render_func(ctx)]  # type: ignore
    ^^^^^^^^^^^^^^^^^^^^^^^^^^^^^^^^^^^^^^^^^^^^^
  File "/home/runner/TelegramLoginWidget/templates/index.html", line 1, in top-level template code
    {% extends "base.html" %}
  File "/home/runner/TelegramLoginWidget/templates/base.html", line 15, in top-level template code
    <li><a href="{{ url_for('profile') }}">Profile</a></li>
    ^^^^^^^^^^^^^^^^^^^^^^^^^
  File "/home/runner/TelegramLoginWidget/.pythonlibs/lib/python3.11/site-packages/quart/app.py", line 734, in url_for
    return self.handle_url_build_error(error, endpoint, values)
           ^^^^^^^^^^^^^^^^^^^^^^^^^^^^^^^^^^^^^^^^^^^^^^^^^^^^
  File "/home/runner/TelegramLoginWidget/.pythonlibs/lib/python3.11/site-packages/quart/app.py", line 732, in url_for
    url = url_adapter.build(endpoint, values, method=_method, force_external=_external)
          ^^^^^^^^^^^^^^^^^^^^^^^^^^^^^^^^^^^^^^^^^^^^^^^^^^^^^^^^^^^^^^^^^^^^^^^^^^^^^
  File "/home/runner/TelegramLoginWidget/.pythonlibs/lib/python3.11/site-packages/werkzeug/routing/map.py", line 924, in build
    raise BuildError(endpoint, values, method, self)
werkzeug.routing.exceptions.BuildError: Could not build url for endpoint 'profile'. Did you mean 'index' instead?

During handling of the above exception, another exception occurred:

Traceback (most recent call last):
  File "/home/runner/TelegramLoginWidget/.pythonlibs/lib/python3.11/site-packages/hypercorn/asyncio/task_group.py", line 27, in _handle
    await app(scope, receive, send, sync_spawn, call_soon)
  File "/home/runner/TelegramLoginWidget/.pythonlibs/lib/python3.11/site-packages/hypercorn/app_wrappers.py", line 34, in __call__
    await self.app(scope, receive, send)
  File "/home/runner/TelegramLoginWidget/.pythonlibs/lib/python3.11/site-packages/quart/app.py", line 1667, in __call__
    await self.asgi_app(scope, receive, send)
  File "/home/runner/TelegramLoginWidget/.pythonlibs/lib/python3.11/site-packages/quart/app.py", line 1693, in asgi_app
    await asgi_handler(receive, send)
  File "/home/runner/TelegramLoginWidget/.pythonlibs/lib/python3.11/site-packages/quart/asgi.py", line 52, in __call__
    raise_task_exceptions(done)
  File "/home/runner/TelegramLoginWidget/.pythonlibs/lib/python3.11/site-packages/quart/utils.py", line 180, in raise_task_exceptions
    raise task.exception()
  File "/home/runner/TelegramLoginWidget/.pythonlibs/lib/python3.11/site-packages/quart/asgi.py", line 100, in handle_request
    response = await _handle_exception(self.app, error)
               ^^^^^^^^^^^^^^^^^^^^^^^^^^^^^^^^^^^^^^^^
  File "/home/runner/TelegramLoginWidget/.pythonlibs/lib/python3.11/site-packages/quart/asgi.py", line 357, in _handle_exception
    raise error
  File "/home/runner/TelegramLoginWidget/.pythonlibs/lib/python3.11/site-packages/quart/asgi.py", line 98, in handle_request
    response = await self.app.handle_request(request)
               ^^^^^^^^^^^^^^^^^^^^^^^^^^^^^^^^^^^^^^
  File "/home/runner/TelegramLoginWidget/.pythonlibs/lib/python3.11/site-packages/quart/app.py", line 1407, in handle_request
    return await self.handle_exception(error)
           ^^^^^^^^^^^^^^^^^^^^^^^^^^^^^^^^^^
  File "/home/runner/TelegramLoginWidget/.pythonlibs/lib/python3.11/site-packages/quart/app.py", line 1061, in handle_exception
    server_error = await self.ensure_async(handler)(server_error)  # type: ignore
                   ^^^^^^^^^^^^^^^^^^^^^^^^^^^^^^^^^^^^^^^^^^^^^^
  File "/home/runner/TelegramLoginWidget/app.py", line 94, in internal_error
    return await render_template('errors/500.html'), 500
           ^^^^^^^^^^^^^^^^^^^^^^^^^^^^^^^^^^^^^^^^
  File "/home/runner/TelegramLoginWidget/.pythonlibs/lib/python3.11/site-packages/quart/templating.py", line 47, in render_template
    return await _render(template, context, current_app._get_current_object())  # type: ignore
           ^^^^^^^^^^^^^^^^^^^^^^^^^^^^^^^^^^^^^^^^^^^^^^^^^^^^^^^^^^^^^^^^^^^
  File "/home/runner/TelegramLoginWidget/.pythonlibs/lib/python3.11/site-packages/quart/templating.py", line 66, in _render
    rendered_template = await template.render_async(context)
                        ^^^^^^^^^^^^^^^^^^^^^^^^^^^^^^^^^^^^
  File "/home/runner/TelegramLoginWidget/.pythonlibs/lib/python3.11/site-packages/jinja2/environment.py", line 1327, in render_async
    return self.environment.handle_exception()
           ^^^^^^^^^^^^^^^^^^^^^^^^^^^^^^^^^^^
  File "/home/runner/TelegramLoginWidget/.pythonlibs/lib/python3.11/site-packages/jinja2/environment.py", line 939, in handle_exception
    raise rewrite_traceback_stack(source=source)
  File "/home/runner/TelegramLoginWidget/.pythonlibs/lib/python3.11/site-packages/jinja2/environment.py", line 1324, in <listcomp>
    [n async for n in self.root_render_func(ctx)]  # type: ignore
    ^^^^^^^^^^^^^^^^^^^^^^^^^^^^^^^^^^^^^^^^^^^^^
  File "/home/runner/TelegramLoginWidget/templates/errors/500.html", line 1, in top-level template code
    {% extends 'base.html' %}
  File "/home/runner/TelegramLoginWidget/templates/base.html", line 15, in top-level template code
    <li><a href="{{ url_for('profile') }}">Profile</a></li>
    ^^^^^^^^^^^^^^^^^^^^^^^^^
  File "/home/runner/TelegramLoginWidget/.pythonlibs/lib/python3.11/site-packages/quart/app.py", line 734, in url_for
    return self.handle_url_build_error(error, endpoint, values)
           ^^^^^^^^^^^^^^^^^^^^^^^^^^^^^^^^^^^^^^^^^^^^^^^^^^^^
  File "/home/runner/TelegramLoginWidget/.pythonlibs/lib/python3.11/site-packages/quart/app.py", line 732, in url_for
    url = url_adapter.build(endpoint, values, method=_method, force_external=_external)
          ^^^^^^^^^^^^^^^^^^^^^^^^^^^^^^^^^^^^^^^^^^^^^^^^^^^^^^^^^^^^^^^^^^^^^^^^^^^^^
  File "/home/runner/TelegramLoginWidget/.pythonlibs/lib/python3.11/site-packages/werkzeug/routing/map.py", line 924, in build
    raise BuildError(endpoint, values, method, self)
werkzeug.routing.exceptions.BuildError: Could not build url for endpoint 'profile'. Did you mean 'index' instead?
2024-09-24 20:18:36,689 - app - ERROR - Exception on request GET /
Traceback (most recent call last):
  File "/home/runner/TelegramLoginWidget/.pythonlibs/lib/python3.11/site-packages/quart/app.py", line 1403, in handle_request
    return await self.full_dispatch_request(request_context)
           ^^^^^^^^^^^^^^^^^^^^^^^^^^^^^^^^^^^^^^^^^^^^^^^^^
  File "/home/runner/TelegramLoginWidget/.pythonlibs/lib/python3.11/site-packages/quart/app.py", line 1441, in full_dispatch_request
    result = await self.handle_user_exception(error)
             ^^^^^^^^^^^^^^^^^^^^^^^^^^^^^^^^^^^^^^^
  File "/home/runner/TelegramLoginWidget/.pythonlibs/lib/python3.11/site-packages/quart/app.py", line 1029, in handle_user_exception
    raise error
  File "/home/runner/TelegramLoginWidget/.pythonlibs/lib/python3.11/site-packages/quart/app.py", line 1439, in full_dispatch_request
    result = await self.dispatch_request(request_context)
             ^^^^^^^^^^^^^^^^^^^^^^^^^^^^^^^^^^^^^^^^^^^^
  File "/home/runner/TelegramLoginWidget/.pythonlibs/lib/python3.11/site-packages/quart/app.py", line 1535, in dispatch_request
    return await self.ensure_async(handler)(**request_.view_args)  # type: ignore
           ^^^^^^^^^^^^^^^^^^^^^^^^^^^^^^^^^^^^^^^^^^^^^^^^^^^^^^
  File "/home/runner/TelegramLoginWidget/app.py", line 33, in index
    return await render_template('index.html')
           ^^^^^^^^^^^^^^^^^^^^^^^^^^^^^^^^^^^
  File "/home/runner/TelegramLoginWidget/.pythonlibs/lib/python3.11/site-packages/quart/templating.py", line 47, in render_template
    return await _render(template, context, current_app._get_current_object())  # type: ignore
           ^^^^^^^^^^^^^^^^^^^^^^^^^^^^^^^^^^^^^^^^^^^^^^^^^^^^^^^^^^^^^^^^^^^
  File "/home/runner/TelegramLoginWidget/.pythonlibs/lib/python3.11/site-packages/quart/templating.py", line 66, in _render
    rendered_template = await template.render_async(context)
                        ^^^^^^^^^^^^^^^^^^^^^^^^^^^^^^^^^^^^
  File "/home/runner/TelegramLoginWidget/.pythonlibs/lib/python3.11/site-packages/jinja2/environment.py", line 1327, in render_async
    return self.environment.handle_exception()
           ^^^^^^^^^^^^^^^^^^^^^^^^^^^^^^^^^^^
  File "/home/runner/TelegramLoginWidget/.pythonlibs/lib/python3.11/site-packages/jinja2/environment.py", line 939, in handle_exception
    raise rewrite_traceback_stack(source=source)
  File "/home/runner/TelegramLoginWidget/.pythonlibs/lib/python3.11/site-packages/jinja2/environment.py", line 1324, in <listcomp>
    [n async for n in self.root_render_func(ctx)]  # type: ignore
    ^^^^^^^^^^^^^^^^^^^^^^^^^^^^^^^^^^^^^^^^^^^^^
  File "/home/runner/TelegramLoginWidget/templates/index.html", line 1, in top-level template code
    {% extends "base.html" %}
  File "/home/runner/TelegramLoginWidget/templates/base.html", line 15, in top-level template code
    <li><a href="{{ url_for('profile') }}">Profile</a></li>
    ^^^^^^^^^^^^^^^^^^^^^^^^^
  File "/home/runner/TelegramLoginWidget/.pythonlibs/lib/python3.11/site-packages/quart/app.py", line 734, in url_for
    return self.handle_url_build_error(error, endpoint, values)
           ^^^^^^^^^^^^^^^^^^^^^^^^^^^^^^^^^^^^^^^^^^^^^^^^^^^^
  File "/home/runner/TelegramLoginWidget/.pythonlibs/lib/python3.11/site-packages/quart/app.py", line 732, in url_for
    url = url_adapter.build(endpoint, values, method=_method, force_external=_external)
          ^^^^^^^^^^^^^^^^^^^^^^^^^^^^^^^^^^^^^^^^^^^^^^^^^^^^^^^^^^^^^^^^^^^^^^^^^^^^^
  File "/home/runner/TelegramLoginWidget/.pythonlibs/lib/python3.11/site-packages/werkzeug/routing/map.py", line 924, in build
    raise BuildError(endpoint, values, method, self)
werkzeug.routing.exceptions.BuildError: Could not build url for endpoint 'profile'. Did you mean 'index' instead?
[2024-09-24 20:18:36 +0000] [4064] [ERROR] Error in ASGI Framework
Traceback (most recent call last):
  File "/home/runner/TelegramLoginWidget/.pythonlibs/lib/python3.11/site-packages/quart/app.py", line 1403, in handle_request
    return await self.full_dispatch_request(request_context)
           ^^^^^^^^^^^^^^^^^^^^^^^^^^^^^^^^^^^^^^^^^^^^^^^^^
  File "/home/runner/TelegramLoginWidget/.pythonlibs/lib/python3.11/site-packages/quart/app.py", line 1441, in full_dispatch_request
    result = await self.handle_user_exception(error)
             ^^^^^^^^^^^^^^^^^^^^^^^^^^^^^^^^^^^^^^^
  File "/home/runner/TelegramLoginWidget/.pythonlibs/lib/python3.11/site-packages/quart/app.py", line 1029, in handle_user_exception
    raise error
  File "/home/runner/TelegramLoginWidget/.pythonlibs/lib/python3.11/site-packages/quart/app.py", line 1439, in full_dispatch_request
    result = await self.dispatch_request(request_context)
             ^^^^^^^^^^^^^^^^^^^^^^^^^^^^^^^^^^^^^^^^^^^^
  File "/home/runner/TelegramLoginWidget/.pythonlibs/lib/python3.11/site-packages/quart/app.py", line 1535, in dispatch_request
    return await self.ensure_async(handler)(**request_.view_args)  # type: ignore
           ^^^^^^^^^^^^^^^^^^^^^^^^^^^^^^^^^^^^^^^^^^^^^^^^^^^^^^
  File "/home/runner/TelegramLoginWidget/app.py", line 33, in index
    return await render_template('index.html')
           ^^^^^^^^^^^^^^^^^^^^^^^^^^^^^^^^^^^
  File "/home/runner/TelegramLoginWidget/.pythonlibs/lib/python3.11/site-packages/quart/templating.py", line 47, in render_template
    return await _render(template, context, current_app._get_current_object())  # type: ignore
           ^^^^^^^^^^^^^^^^^^^^^^^^^^^^^^^^^^^^^^^^^^^^^^^^^^^^^^^^^^^^^^^^^^^
  File "/home/runner/TelegramLoginWidget/.pythonlibs/lib/python3.11/site-packages/quart/templating.py", line 66, in _render
    rendered_template = await template.render_async(context)
                        ^^^^^^^^^^^^^^^^^^^^^^^^^^^^^^^^^^^^
  File "/home/runner/TelegramLoginWidget/.pythonlibs/lib/python3.11/site-packages/jinja2/environment.py", line 1327, in render_async
    return self.environment.handle_exception()
           ^^^^^^^^^^^^^^^^^^^^^^^^^^^^^^^^^^^
  File "/home/runner/TelegramLoginWidget/.pythonlibs/lib/python3.11/site-packages/jinja2/environment.py", line 939, in handle_exception
    raise rewrite_traceback_stack(source=source)
  File "/home/runner/TelegramLoginWidget/.pythonlibs/lib/python3.11/site-packages/jinja2/environment.py", line 1324, in <listcomp>
    [n async for n in self.root_render_func(ctx)]  # type: ignore
    ^^^^^^^^^^^^^^^^^^^^^^^^^^^^^^^^^^^^^^^^^^^^^
  File "/home/runner/TelegramLoginWidget/templates/index.html", line 1, in top-level template code
    {% extends "base.html" %}
  File "/home/runner/TelegramLoginWidget/templates/base.html", line 15, in top-level template code
    <li><a href="{{ url_for('profile') }}">Profile</a></li>
    ^^^^^^^^^^^^^^^^^^^^^^^^^
  File "/home/runner/TelegramLoginWidget/.pythonlibs/lib/python3.11/site-packages/quart/app.py", line 734, in url_for
    return self.handle_url_build_error(error, endpoint, values)
           ^^^^^^^^^^^^^^^^^^^^^^^^^^^^^^^^^^^^^^^^^^^^^^^^^^^^
  File "/home/runner/TelegramLoginWidget/.pythonlibs/lib/python3.11/site-packages/quart/app.py", line 732, in url_for
    url = url_adapter.build(endpoint, values, method=_method, force_external=_external)
          ^^^^^^^^^^^^^^^^^^^^^^^^^^^^^^^^^^^^^^^^^^^^^^^^^^^^^^^^^^^^^^^^^^^^^^^^^^^^^
  File "/home/runner/TelegramLoginWidget/.pythonlibs/lib/python3.11/site-packages/werkzeug/routing/map.py", line 924, in build
    raise BuildError(endpoint, values, method, self)
werkzeug.routing.exceptions.BuildError: Could not build url for endpoint 'profile'. Did you mean 'index' instead?

During handling of the above exception, another exception occurred:

Traceback (most recent call last):
  File "/home/runner/TelegramLoginWidget/.pythonlibs/lib/python3.11/site-packages/hypercorn/asyncio/task_group.py", line 27, in _handle
    await app(scope, receive, send, sync_spawn, call_soon)
  File "/home/runner/TelegramLoginWidget/.pythonlibs/lib/python3.11/site-packages/hypercorn/app_wrappers.py", line 34, in __call__
    await self.app(scope, receive, send)
  File "/home/runner/TelegramLoginWidget/.pythonlibs/lib/python3.11/site-packages/quart/app.py", line 1667, in __call__
    await self.asgi_app(scope, receive, send)
  File "/home/runner/TelegramLoginWidget/.pythonlibs/lib/python3.11/site-packages/quart/app.py", line 1693, in asgi_app
    await asgi_handler(receive, send)
  File "/home/runner/TelegramLoginWidget/.pythonlibs/lib/python3.11/site-packages/quart/asgi.py", line 52, in __call__
    raise_task_exceptions(done)
  File "/home/runner/TelegramLoginWidget/.pythonlibs/lib/python3.11/site-packages/quart/utils.py", line 180, in raise_task_exceptions
    raise task.exception()
  File "/home/runner/TelegramLoginWidget/.pythonlibs/lib/python3.11/site-packages/quart/asgi.py", line 100, in handle_request
    response = await _handle_exception(self.app, error)
               ^^^^^^^^^^^^^^^^^^^^^^^^^^^^^^^^^^^^^^^^
  File "/home/runner/TelegramLoginWidget/.pythonlibs/lib/python3.11/site-packages/quart/asgi.py", line 357, in _handle_exception
    raise error
  File "/home/runner/TelegramLoginWidget/.pythonlibs/lib/python3.11/site-packages/quart/asgi.py", line 98, in handle_request
    response = await self.app.handle_request(request)
               ^^^^^^^^^^^^^^^^^^^^^^^^^^^^^^^^^^^^^^
  File "/home/runner/TelegramLoginWidget/.pythonlibs/lib/python3.11/site-packages/quart/app.py", line 1407, in handle_request
    return await self.handle_exception(error)
           ^^^^^^^^^^^^^^^^^^^^^^^^^^^^^^^^^^
  File "/home/runner/TelegramLoginWidget/.pythonlibs/lib/python3.11/site-packages/quart/app.py", line 1061, in handle_exception
    server_error = await self.ensure_async(handler)(server_error)  # type: ignore
                   ^^^^^^^^^^^^^^^^^^^^^^^^^^^^^^^^^^^^^^^^^^^^^^
  File "/home/runner/TelegramLoginWidget/app.py", line 94, in internal_error
    return await render_template('errors/500.html'), 500
           ^^^^^^^^^^^^^^^^^^^^^^^^^^^^^^^^^^^^^^^^
  File "/home/runner/TelegramLoginWidget/.pythonlibs/lib/python3.11/site-packages/quart/templating.py", line 47, in render_template
    return await _render(template, context, current_app._get_current_object())  # type: ignore
           ^^^^^^^^^^^^^^^^^^^^^^^^^^^^^^^^^^^^^^^^^^^^^^^^^^^^^^^^^^^^^^^^^^^
  File "/home/runner/TelegramLoginWidget/.pythonlibs/lib/python3.11/site-packages/quart/templating.py", line 66, in _render
    rendered_template = await template.render_async(context)
                        ^^^^^^^^^^^^^^^^^^^^^^^^^^^^^^^^^^^^
  File "/home/runner/TelegramLoginWidget/.pythonlibs/lib/python3.11/site-packages/jinja2/environment.py", line 1327, in render_async
    return self.environment.handle_exception()
           ^^^^^^^^^^^^^^^^^^^^^^^^^^^^^^^^^^^
  File "/home/runner/TelegramLoginWidget/.pythonlibs/lib/python3.11/site-packages/jinja2/environment.py", line 939, in handle_exception
    raise rewrite_traceback_stack(source=source)
  File "/home/runner/TelegramLoginWidget/.pythonlibs/lib/python3.11/site-packages/jinja2/environment.py", line 1324, in <listcomp>
    [n async for n in self.root_render_func(ctx)]  # type: ignore
    ^^^^^^^^^^^^^^^^^^^^^^^^^^^^^^^^^^^^^^^^^^^^^
  File "/home/runner/TelegramLoginWidget/templates/errors/500.html", line 1, in top-level template code
    {% extends 'base.html' %}
  File "/home/runner/TelegramLoginWidget/templates/base.html", line 15, in top-level template code
    <li><a href="{{ url_for('profile') }}">Profile</a></li>
    ^^^^^^^^^^^^^^^^^^^^^^^^^
  File "/home/runner/TelegramLoginWidget/.pythonlibs/lib/python3.11/site-packages/quart/app.py", line 734, in url_for
    return self.handle_url_build_error(error, endpoint, values)
           ^^^^^^^^^^^^^^^^^^^^^^^^^^^^^^^^^^^^^^^^^^^^^^^^^^^^
  File "/home/runner/TelegramLoginWidget/.pythonlibs/lib/python3.11/site-packages/quart/app.py", line 732, in url_for
    url = url_adapter.build(endpoint, values, method=_method, force_external=_external)
          ^^^^^^^^^^^^^^^^^^^^^^^^^^^^^^^^^^^^^^^^^^^^^^^^^^^^^^^^^^^^^^^^^^^^^^^^^^^^^
  File "/home/runner/TelegramLoginWidget/.pythonlibs/lib/python3.11/site-packages/werkzeug/routing/map.py", line 924, in build
    raise BuildError(endpoint, values, method, self)
werkzeug.routing.exceptions.BuildError: Could not build url for endpoint 'profile'. Did you mean 'index' instead?
2024-09-24 20:18:36,692 - hypercorn.error - ERROR - Error in ASGI Framework
Traceback (most recent call last):
  File "/home/runner/TelegramLoginWidget/.pythonlibs/lib/python3.11/site-packages/quart/app.py", line 1403, in handle_request
    return await self.full_dispatch_request(request_context)
           ^^^^^^^^^^^^^^^^^^^^^^^^^^^^^^^^^^^^^^^^^^^^^^^^^
  File "/home/runner/TelegramLoginWidget/.pythonlibs/lib/python3.11/site-packages/quart/app.py", line 1441, in full_dispatch_request
    result = await self.handle_user_exception(error)
             ^^^^^^^^^^^^^^^^^^^^^^^^^^^^^^^^^^^^^^^
  File "/home/runner/TelegramLoginWidget/.pythonlibs/lib/python3.11/site-packages/quart/app.py", line 1029, in handle_user_exception
    raise error
  File "/home/runner/TelegramLoginWidget/.pythonlibs/lib/python3.11/site-packages/quart/app.py", line 1439, in full_dispatch_request
    result = await self.dispatch_request(request_context)
             ^^^^^^^^^^^^^^^^^^^^^^^^^^^^^^^^^^^^^^^^^^^^
  File "/home/runner/TelegramLoginWidget/.pythonlibs/lib/python3.11/site-packages/quart/app.py", line 1535, in dispatch_request
    return await self.ensure_async(handler)(**request_.view_args)  # type: ignore
           ^^^^^^^^^^^^^^^^^^^^^^^^^^^^^^^^^^^^^^^^^^^^^^^^^^^^^^
  File "/home/runner/TelegramLoginWidget/app.py", line 33, in index
    return await render_template('index.html')
           ^^^^^^^^^^^^^^^^^^^^^^^^^^^^^^^^^^^
  File "/home/runner/TelegramLoginWidget/.pythonlibs/lib/python3.11/site-packages/quart/templating.py", line 47, in render_template
    return await _render(template, context, current_app._get_current_object())  # type: ignore
           ^^^^^^^^^^^^^^^^^^^^^^^^^^^^^^^^^^^^^^^^^^^^^^^^^^^^^^^^^^^^^^^^^^^
  File "/home/runner/TelegramLoginWidget/.pythonlibs/lib/python3.11/site-packages/quart/templating.py", line 66, in _render
    rendered_template = await template.render_async(context)
                        ^^^^^^^^^^^^^^^^^^^^^^^^^^^^^^^^^^^^
  File "/home/runner/TelegramLoginWidget/.pythonlibs/lib/python3.11/site-packages/jinja2/environment.py", line 1327, in render_async
    return self.environment.handle_exception()
           ^^^^^^^^^^^^^^^^^^^^^^^^^^^^^^^^^^^
  File "/home/runner/TelegramLoginWidget/.pythonlibs/lib/python3.11/site-packages/jinja2/environment.py", line 939, in handle_exception
    raise rewrite_traceback_stack(source=source)
  File "/home/runner/TelegramLoginWidget/.pythonlibs/lib/python3.11/site-packages/jinja2/environment.py", line 1324, in <listcomp>
    [n async for n in self.root_render_func(ctx)]  # type: ignore
    ^^^^^^^^^^^^^^^^^^^^^^^^^^^^^^^^^^^^^^^^^^^^^
  File "/home/runner/TelegramLoginWidget/templates/index.html", line 1, in top-level template code
    {% extends "base.html" %}
  File "/home/runner/TelegramLoginWidget/templates/base.html", line 15, in top-level template code
    <li><a href="{{ url_for('profile') }}">Profile</a></li>
    ^^^^^^^^^^^^^^^^^^^^^^^^^
  File "/home/runner/TelegramLoginWidget/.pythonlibs/lib/python3.11/site-packages/quart/app.py", line 734, in url_for
    return self.handle_url_build_error(error, endpoint, values)
           ^^^^^^^^^^^^^^^^^^^^^^^^^^^^^^^^^^^^^^^^^^^^^^^^^^^^
  File "/home/runner/TelegramLoginWidget/.pythonlibs/lib/python3.11/site-packages/quart/app.py", line 732, in url_for
    url = url_adapter.build(endpoint, values, method=_method, force_external=_external)
          ^^^^^^^^^^^^^^^^^^^^^^^^^^^^^^^^^^^^^^^^^^^^^^^^^^^^^^^^^^^^^^^^^^^^^^^^^^^^^
  File "/home/runner/TelegramLoginWidget/.pythonlibs/lib/python3.11/site-packages/werkzeug/routing/map.py", line 924, in build
    raise BuildError(endpoint, values, method, self)
werkzeug.routing.exceptions.BuildError: Could not build url for endpoint 'profile'. Did you mean 'index' instead?

During handling of the above exception, another exception occurred:

Traceback (most recent call last):
  File "/home/runner/TelegramLoginWidget/.pythonlibs/lib/python3.11/site-packages/hypercorn/asyncio/task_group.py", line 27, in _handle
    await app(scope, receive, send, sync_spawn, call_soon)
  File "/home/runner/TelegramLoginWidget/.pythonlibs/lib/python3.11/site-packages/hypercorn/app_wrappers.py", line 34, in __call__
    await self.app(scope, receive, send)
  File "/home/runner/TelegramLoginWidget/.pythonlibs/lib/python3.11/site-packages/quart/app.py", line 1667, in __call__
    await self.asgi_app(scope, receive, send)
  File "/home/runner/TelegramLoginWidget/.pythonlibs/lib/python3.11/site-packages/quart/app.py", line 1693, in asgi_app
    await asgi_handler(receive, send)
  File "/home/runner/TelegramLoginWidget/.pythonlibs/lib/python3.11/site-packages/quart/asgi.py", line 52, in __call__
    raise_task_exceptions(done)
  File "/home/runner/TelegramLoginWidget/.pythonlibs/lib/python3.11/site-packages/quart/utils.py", line 180, in raise_task_exceptions
    raise task.exception()
  File "/home/runner/TelegramLoginWidget/.pythonlibs/lib/python3.11/site-packages/quart/asgi.py", line 100, in handle_request
    response = await _handle_exception(self.app, error)
               ^^^^^^^^^^^^^^^^^^^^^^^^^^^^^^^^^^^^^^^^
  File "/home/runner/TelegramLoginWidget/.pythonlibs/lib/python3.11/site-packages/quart/asgi.py", line 357, in _handle_exception
    raise error
  File "/home/runner/TelegramLoginWidget/.pythonlibs/lib/python3.11/site-packages/quart/asgi.py", line 98, in handle_request
    response = await self.app.handle_request(request)
               ^^^^^^^^^^^^^^^^^^^^^^^^^^^^^^^^^^^^^^
  File "/home/runner/TelegramLoginWidget/.pythonlibs/lib/python3.11/site-packages/quart/app.py", line 1407, in handle_request
    return await self.handle_exception(error)
           ^^^^^^^^^^^^^^^^^^^^^^^^^^^^^^^^^^
  File "/home/runner/TelegramLoginWidget/.pythonlibs/lib/python3.11/site-packages/quart/app.py", line 1061, in handle_exception
    server_error = await self.ensure_async(handler)(server_error)  # type: ignore
                   ^^^^^^^^^^^^^^^^^^^^^^^^^^^^^^^^^^^^^^^^^^^^^^
  File "/home/runner/TelegramLoginWidget/app.py", line 94, in internal_error
    return await render_template('errors/500.html'), 500
           ^^^^^^^^^^^^^^^^^^^^^^^^^^^^^^^^^^^^^^^^
  File "/home/runner/TelegramLoginWidget/.pythonlibs/lib/python3.11/site-packages/quart/templating.py", line 47, in render_template
    return await _render(template, context, current_app._get_current_object())  # type: ignore
           ^^^^^^^^^^^^^^^^^^^^^^^^^^^^^^^^^^^^^^^^^^^^^^^^^^^^^^^^^^^^^^^^^^^
  File "/home/runner/TelegramLoginWidget/.pythonlibs/lib/python3.11/site-packages/quart/templating.py", line 66, in _render
    rendered_template = await template.render_async(context)
                        ^^^^^^^^^^^^^^^^^^^^^^^^^^^^^^^^^^^^
  File "/home/runner/TelegramLoginWidget/.pythonlibs/lib/python3.11/site-packages/jinja2/environment.py", line 1327, in render_async
    return self.environment.handle_exception()
           ^^^^^^^^^^^^^^^^^^^^^^^^^^^^^^^^^^^
  File "/home/runner/TelegramLoginWidget/.pythonlibs/lib/python3.11/site-packages/jinja2/environment.py", line 939, in handle_exception
    raise rewrite_traceback_stack(source=source)
  File "/home/runner/TelegramLoginWidget/.pythonlibs/lib/python3.11/site-packages/jinja2/environment.py", line 1324, in <listcomp>
    [n async for n in self.root_render_func(ctx)]  # type: ignore
    ^^^^^^^^^^^^^^^^^^^^^^^^^^^^^^^^^^^^^^^^^^^^^
  File "/home/runner/TelegramLoginWidget/templates/errors/500.html", line 1, in top-level template code
    {% extends 'base.html' %}
  File "/home/runner/TelegramLoginWidget/templates/base.html", line 15, in top-level template code
    <li><a href="{{ url_for('profile') }}">Profile</a></li>
    ^^^^^^^^^^^^^^^^^^^^^^^^^
  File "/home/runner/TelegramLoginWidget/.pythonlibs/lib/python3.11/site-packages/quart/app.py", line 734, in url_for
    return self.handle_url_build_error(error, endpoint, values)
           ^^^^^^^^^^^^^^^^^^^^^^^^^^^^^^^^^^^^^^^^^^^^^^^^^^^^
  File "/home/runner/TelegramLoginWidget/.pythonlibs/lib/python3.11/site-packages/quart/app.py", line 732, in url_for
    url = url_adapter.build(endpoint, values, method=_method, force_external=_external)
          ^^^^^^^^^^^^^^^^^^^^^^^^^^^^^^^^^^^^^^^^^^^^^^^^^^^^^^^^^^^^^^^^^^^^^^^^^^^^^
  File "/home/runner/TelegramLoginWidget/.pythonlibs/lib/python3.11/site-packages/werkzeug/routing/map.py", line 924, in build
    raise BuildError(endpoint, values, method, self)
werkzeug.routing.exceptions.BuildError: Could not build url for endpoint 'profile'. Did you mean 'index' instead?